Workbook

Sheet RK1
A1: Hoppenbrouwers Techniek BV
A2: Kreitemolenstraat 201
A3: 5071 ND Udenhout
A4: T: 013 5117227
A5: F: 013 5114145
A7: Project: | B7: Kindcentrum Chaam
A8: Projectnummer: | B8: 2605577
A9: Opgesteld: | B9: S. Timmermans
A10: Status: | B10: Calculatie/Ontwerp
A11: Datum: | B11: 46237
A14: Regelkast: | D14: Bedrijfmelding | E14: Storingsmelding | F14: Analoge ingang | G14: Digitale uitgang | H14: Analoge uitgang | I14: Verzend waarde | J14: Ontvang waarde | K14: P [kW] | L14: I [A] | M14: U [V] | O14: Sturen | P14: Meten | Q14: Fabricaat | R14: Type
A15: Document nr:
A16: Bladnummer: | C16: Bestek
N20: Preferent 2
A21: I/O check | B21: Omschrijving | C21: Proces code | D21: B | E21: ST | F21: AI | G21: I/O | H21: AU | I21: VW | J21: OW
B22: Algemeen
B23: Buitentemperatuuropnemer | D23: - | E23: - | F23: 2 | G23: - | H23: - | I23: - | J23: - | M23: 24
B24: Verzamel storingsmelding urgent (front deur) | D24: - | E24: - | F24: - | G24: 1 | H24: - | I24: - | J24: -
B25: Verzamel storingsmelding niet-urgent (front deur) | D25: - | E25: - | F25: - | G25: 1 | H25: - | I25: - | J25: -
B26: Reset storingsmelding (drukknop op front) | D26: - | E26: - | F26: - | G26: 1 | H26: - | I26: - | J26: -
B27: Brandmelding Brandmeldcentrale (levering E-installateur) | D27: - | E27: - | F27: - | G27: 1 | H27: - | I27: - | J27: -
B28: Signalering Brandsituatie (front deur) | D28: - | E28: - | F28: - | G28: 1 | H28: - | I28: - | J28: -
B29: Brandschakelaar toevoer (brandpaneel levering E-installateur) | D29: - | E29: - | F29: - | G29: 2 | H29: - | I29: - | J29: -
B30: Brandschakelaar afvoer (brandpaneel levering E-installateur) | D30: - | E30: - | F30: - | G30: 2 | H30: - | I30: - | J30: -
B31: Signalering brandklep (verzameld) | D31: - | E31: - | F31: - | G31: 1 | H31: - | I31: - | J31: -
B33: Warmtepomp 1
B34: Warmtepomp. | D34: - | E34: - | F34: - | G34: - | H34: - | I34: 5 | J34: 10 | K34: Hopp-E | P34: Modbus-RTU
B35: Warmtepomp. Vrijgave | D35: - | E35: - | F35: - | G35: 1 | H35: - | I35: - | J35: -
B36: Warmtepomp. Storing | D36: - | E36: 1 | F36: - | G36: - | H36: - | I36: - | J36: -
B37: Warmtepomp. Vermogen sturing | D37: - | E37: - | F37: - | G37: - | H37: 1 | I37: - | J37: -
B38: Tracing. Vrijgave | D38: - | E38: - | F38: - | G38: 1 | H38: - | I38: - | J38: - | K38: 1.5 | M38: 230
B39: Tracing. Storing | D39: - | E39: 1 | F39: - | G39: - | H39: - | I39: - | J39: -
B40: 3-weg afsluiter | D40: - | E40: - | F40: - | G40: - | H40: 1 | I40: - | J40: - | R40: VXF22.80-100 - DN80
B41: Aanvoer temperatuur | D41: - | E41: - | F41: 1 | G41: - | H41: - | I41: - | J41: - | Q41: Siemens | R41: QAE2120.010
B42: Retour temperatuur | D42: - | E42: - | F42: 1 | G42: - | H42: - | I42: - | J42: - | Q42: Siemens | R42: QAE2120.010
B43: Energiemeter | D43: - | E43: - | F43: - | G43: - | H43: - | I43: - | J43: 4 | L43: 6 | M43: 230 | P43: Bacnet MS/TP
B45: Warmtepomp 2
B46: Warmtepomp. | D46: - | E46: - | F46: - | G46: - | H46: - | I46: 5 | J46: 10 | K46: Hopp-E | P46: Modbus-RTU
B47: Warmtepomp. Vrijgave | D47: - | E47: - | F47: - | G47: 1 | H47: - | I47: - | J47: -
B48: Warmtepomp. Storing | D48: - | E48: 1 | F48: - | G48: - | H48: - | I48: - | J48: -
...

Sheet Naregelingen
A1: Hoppenbrouwers Techniek BV
A2: Kreitemolenstraat 201
A3: 5071 ND Udenhout
A4: T: 013 5117227
A5: F: 013 5114145
A7: Project: | B7: Kindcentrum Chaam
A8: Projectnummer: | B8: 2605577
A9: Opgesteld: | B9: Sven Timmermans
A10: Status: | B10: ='RK1'!B10 -> Calculatie/Ontwerp
A11: Datum: | B11: 46237
A14: Lokaal/ruimte nr. | B14: Aantal | C14: Naregelaar benaming | S14: modulen | Z14: 2-weg klep CV 0 - 10 V - DN15 | AA14: 2-weg klep CV 0 - 10 V - DN20 | AB14: 2-weg klep CV 0 - 10 V - DN25 | AC14: VAV klep Toevoer | AD14: VAV Retour | AE14: E- kanaal verwarmer 0 - 10 V | AF14: 2-weg klep GWK 0 - 10 V - DN25 | AG14: FCU ventilator stand 0 - 10 V | AH14: Change over koelklep | AI14: Vrijgave vloerverwarming | AJ14: Aanvullende digitale uitgang gebruikt | AK14: Aanvullende meting gebruikt | AL14: Opmerking(en)
D15: Priva Comforte CX2 naregelaar | E15: Voedingmodule 230V | F15: Touchpoint One | G15: Analoge-uitgangsmodule | H15: OFTF Ni1000 TK5000 | N15: Serie nr. | O15: OS nr. | AM15: Opmerking(en) | AN15: Naregeling type v.b. schema | AO15: Opmerking
A16: Typical VAV + Naverwarmer | B16: 18 | D16: 18 | E16: 18 | F16: 18 | AA16: 18 | AC16: 18 | AD16: 1
A17: Typical VAV + naverwarmer + vloerverwarming | B17: 19 | D17: 19 | E17: 19 | F17: 19 | AA17: 19 | AC17: 19 | AD17: 1 | AI17: 19
A18: Typical VAV + naverwarmer + plenum retour | B18: 6 | D18: 6 | E18: 6 | F18: 6 | G18: 6 | AA18: 6 | AC18: 6 | AD18: 6
A19: Typical CAV + naverwarmer | B19: 12 | D19: 12 | E19: 12 | F19: 12 | AA19: 12
A20: Typical vloerverwarmingsverdeler (max. 3 groepen) | B20: 7 | D20: 7 | E20: 7 | H20: 7 | AI20: 7
A21: Typical gymzaal middels VRF | B21: 2 | D21: 2 | E21: 2 | F21: 2 | AC21: 2 | AD21: 2
D26: =SUM(D16:D24) -> 64 | E26: =SUM(E16:E24) -> 64 | F26: =SUM(F16:F24) -> 57 | G26: =SUM(G16:G24) -> 6 | H26: =SUM(H16:H24) -> 7 | I26: =SUM(I16:I24) -> 0 | J26: =SUM(J16:J24) -> 0 | K26: =SUM(K16:K24) -> 0 | ... M26: =SUM(M16:M24) -> 0 | Z26: =SUM(Z16:Z24) -> 0 | AA26: =SUM(AA16:AA24) -> 55 | AB26: =SUM(AB16:AB24) -> 0 | AC26: =SUM(AC16:AC24) -> 45 | AD26: =SUM(AD16:AD24) -> 10 | AE26: =SUM(AE16:AE24) -> 0 | AF26: =SUM(AF16:AF24) -> 0 | AG26: =SUM(AG16:AG24) -> 0 | AI26: =SUM(AI16:AI24) -> 26 | AJ26: =SUM(AJ16:AJ24) -> 0 | AK26: =SUM(AK16:AK24) -> 0 | AL26: =SUM(AL16:AL24) -> 0

Sheet E-voorzieningen
A1: Hoppenbrouwers Techniek BV
A2: Kreitemolenstraat 201
A3: 5071 ND Udenhout
A4: T: 013 5117227
A5: F: 013 5114145
A7: Project: | C7: ='RK1'!B7 -> Kindcentrum Chaam
A8: Projectnummer: | C8: ='RK1'!B8 -> 2605577
A9: Opgesteld: | C9: J. Denissen
A10: Status: | C10: ='RK1'!B10 -> Calculatie/Ontwerp
A11: Datum: | C11: ='RK1'!B11 -> 46237
A14: Voedingen
A15: Nummer | B15: Omschrijving | J15: Locatie | K15: U [V] | L15: I [A] | M15: Pw [kW] | N15: Ps [kVa] | O15: Gelijk-tijdigheid [%] | P15: Ptot [kVa] | Q15: Aanbevolen automaat [A] | R15: Kortsluit-stroom [kA] | S15: Karakteristiek | T15: Incl. Nuldraad | U15: kWh-meter | V15: Verdeler | W15: Groep | X15: Kabel diameter | Y15: Opmerking
A16: 1 | P16: =N16*O16 -> 0 | T16: =IF(K16=0,"N.v.t.",IF(K16=24,"N.v.t.",IF(K16=230,"N.v.t.",IF(K16=400,"Ja")))) -> N.v.t.
A17: 2 | P17: =N17*O17 -> 0 | T17: =IF(K17=0,"N.v.t.",IF(K17=24,"N.v.t.",IF(K17=230,"N.v.t.",IF(K17=400,"Ja")))) -> N.v.t.
A18: 3 | N18: =M18/0.9 -> 0 | P18: =N18*O18 -> 0 | T18: =IF(K18=0,"N.v.t.",IF(K18=24,"N.v.t.",IF(K18=230,"N.v.t.",IF(K18=400,"Ja")))) -> N.v.t.
A19: 4 | N19: =M19/0.9 -> 0 | P19: =N19*O19 -> 0 | T19: =IF(K19=0,"N.v.t.",IF(K19=24,"N.v.t.",IF(K19=230,"N.v.t.",IF(K19=400,"Ja")))) -> N.v.t.
A20: 5 | N20: =M20/0.9 -> 0 | P20: =N20*O20 -> 0 | T20: =IF(K20=0,"N.v.t.",IF(K20=24,"N.v.t.",IF(K20=230,"N.v.t.",IF(K20=400,"Ja")))) -> N.v.t.
A21: 6 | N21: =M21/0.9 -> 0 | P21: =N21*O21 -> 0 | T21: =IF(K21=0,"N.v.t.",IF(K21=24,"N.v.t.",IF(K21=230,"N.v.t.",IF(K21=400,"Ja")))) -> N.v.t.
A22: 7 | N22: =M22/0.9 -> 0 | P22: =N22*O22 -> 0 | T22: =IF(K22=0,"N.v.t.",IF(K22=24,"N.v.t.",IF(K22=230,"N.v.t.",IF(K22=400,"Ja")))) -> N.v.t.
A23: 8 | N23: =M23/0.9 -> 0 | P23: =N23*O23 -> 0 | T23: =IF(K23=0,"N.v.t.",IF(K23=24,"N.v.t.",IF(K23=230,"N.v.t.",IF(K23=400,"Ja")))) -> N.v.t.
A24: 9 | N24: =M24/0.9 -> 0 | P24: =N24*O24 -> 0 | T24: =IF(K24=0,"N.v.t.",IF(K24=24,"N.v.t.",IF(K24=230,"N.v.t.",IF(K24=400,"Ja")))) -> N.v.t.
A25: 10 | N25: =M25/0.9 -> 0 | P25: =N25*O25 -> 0 | T25: =IF(K25=0,"N.v.t.",IF(K25=24,"N.v.t.",IF(K25=230,"N.v.t.",IF(K25=400,"Ja")))) -> N.v.t.
N26: =M26/0.9 -> 0 | P26: =N26*O26 -> 0 | T26: =IF(K26=0,"N.v.t.",IF(K26=24,"N.v.t.",IF(K26=230,"N.v.t.",IF(K26=400,"Ja")))) -> N.v.t.
N27: =M27/0.9 -> 0 | P27: =N27*O27 -> 0 | T27: =IF(K27=0,"N.v.t.",IF(K27=24,"N.v.t.",IF(K27=230,"N.v.t.",IF(K27=400,"Ja")))) -> N.v.t.
N28: =M28/0.9 -> 0 | P28: =N28*O28 -> 0 | T28: =IF(K28=0,"N.v.t.",IF(K28=24,"N.v.t.",IF(K28=230,"N.v.t.",IF(K28=400,"Ja")))) -> N.v.t.
N29: =M29/0.9 -> 0 | P29: =N29*O29 -> 0 | T29: =IF(K29=0,"N.v.t.",IF(K29=24,"N.v.t.",IF(K29=230,"N.v.t.",IF(K29=400,"Ja")))) -> N.v.t.
N30: =M30/0.9 -> 0 | P30: =N30*O30 -> 0 | T30: =IF(K30=0,"N.v.t.",IF(K30=24,"N.v.t.",IF(K30=230,"N.v.t.",IF(K30=400,"Ja")))) -> N.v.t.
N31: =M31/0.9 -> 0 | P31: =N31*O31 -> 0 | T31: =IF(K31=0,"N.v.t.",IF(K31=24,"N.v.t.",IF(K31=230,"N.v.t.",IF(K31=400,"Ja")))) -> N.v.t.
N32: =M32/0.9 -> 0 | P32: =N32*O32 -> 0 | T32: =IF(K32=0,"N.v.t.",IF(K32=24,"N.v.t.",IF(K32=230,"N.v.t.",IF(K32=400,"Ja")))) -> N.v.t.
N33: =M33/0.9 -> 0 | P33: =N33*O33 -> 0 | T33: =IF(K33=0,"N.v.t.",IF(K33=24,"N.v.t.",IF(K33=230,"N.v.t.",IF(K33=400,"Ja")))) -> N.v.t.
N34: =M34/0.9 -> 0 | P34: =N34*O34 -> 0 | T34: =IF(K34=0,"N.v.t.",IF(K34=24,"N.v.t.",IF(K34=230,"N.v.t.",IF(K34=400,"Ja")))) -> N.v.t.
N35: =M35/0.9 -> 0 | P35: =N35*O35 -> 0 | T35: =IF(K35=0,"N.v.t.",IF(K35=24,"N.v.t.",IF(K35=230,"N.v.t.",IF(K35=400,"Ja")))) -> N.v.t.
M36: Schijnbaar vermogen | N36: =SUM(N16:N35) -> 0 | O36: kVa
M37: Gemiddelde gelijktijdigheid | N37: =IF(N36=0,0,(SUM(P16:P35)/SUM(N16:N35))) -> 0
M38: Totaal vermogen | N38: =N36*N37 -> 0 | O38: kVa
A41: Voorzieningen
A42: Aantal | B42: Omschrijving | J42: Locatie | K42: Opmerking
A43: 1 | B43: Brandmeldcontact
A44: 12 | B44: Loze voorziening t.b.v. thermostaat
